<mujoco model="sduog48">
    <compiler angle="radian" meshdir="../meshes/" eulerseq="zyx"/>
    <option gravity='0 0 -9.81' solver='PGS'/>
    <size njmax="500" nconmax="100" />
    <asset>
    <texture type="skybox" builtin="gradient" rgb1="0.3 0.5 0.7" rgb2="0 0 0" width="512" height="512" />
    <texture name="texplane" type="2d" builtin="checker" rgb1=".2 .3 .4" rgb2=".1 0.15 0.2" width="512" height="512" mark="cross" markrgb=".8 .8 .8" />
    <material name="matplane" reflectance="0.3" texture="texplane" texrepeat="1 1" texuniform="true" />
        <mesh name="trunk" file="trunk.stl" />
        <mesh name="hip" file="hip.stl" />
        <mesh name="thigh_mirror" file="thigh_mirror.stl" />
        <mesh name="calf" file="calf.stl" />
        <mesh name="thigh" file="thigh.stl" />
    </asset>
    <worldbody>
    <light directional="true" diffuse=".4 .4 .4" specular="0.1 0.1 0.1" pos="0 0 5.0" dir="0 0 -1" castshadow="false" />
    <light directional="true" diffuse=".6 .6 .6" specular="0.2 0.2 0.2" pos="0 0 4" dir="0 0 -1" />
    <geom name="floor" pos="0 0 0" size="100 100 1" type="plane" material="matplane" margin="0.001" contype="1" conaffinity="15" friction="1 0.005 0.0001" />
  
        <body name="trunk" pos="0 0 0.4">
            <inertial pos="-0.00998573 0.00199715 -0.00499287" quat="0.00436269 0.709939 -0.00785922 0.704206" mass="7.01" diaginertia="0.124184 0.107012 0.0303102" />
            <joint name="floating_base_joint" type="free" />
            <geom type="mesh" contype="0" conaffinity="0" group="1" mesh="trunk" />
            <geom size="0.1505 0.1 0.055" type="box" />
            <geom size="0.0075 0.0075 0.002" type="box" contype="0" conaffinity="0" group="1" />
            <body name="FR_hip" pos="0.226 -0.055 0">
                <inertial pos="-0.003311 -0.000635 3.1e-05" quat="0.690882 0.154338 0.153534 0.689413" mass="0.75" diaginertia="0.000775212 0.000502914 0.000502055" />
                <joint name="FR_hip_joint" pos="0 0 0" axis="1 0 0" limited="true" range="-1.0472 1.0472" />
                <geom quat="0 1 0 0" type="mesh" contype="0" conaffinity="0" group="1" rgba="1 0.423529 0.0392157 1" mesh="hip" />
                <geom size="0.045 0.02" quat="0.707107 0.707107 0 0" type="cylinder" rgba="1 0.423529 0.0392157 1" />
                <body name="FR_thigh" pos="0 -0.0875 0">
                    <inertial pos="-0.002 0.023 -0.0263" quat="0.676669 -0.0316401 0.0868634 0.73046" mass="1.25" diaginertia="0.00545464 0.00531835 0.000942016" />
                    <joint name="FR_thigh_joint" pos="0 0 0" axis="0 -1 0" limited="true" range="-3.14159 1.0472" />
                    <geom type="mesh" contype="0" conaffinity="0" group="1" rgba="1 0.423529 0.0392157 1" mesh="thigh_mirror" />
                    <geom size="0.1125 0.01225 0.017" pos="-0.012 0 -0.1125" quat="0.670882 0 0.741564 0" type="box" rgba="1 0.423529 0.0392157 1" />
                    <geom size="0.045 0.02" pos="0 0.025 0" quat="0.707107 0.707107 0 0" type="cylinder" rgba="1 0.423529 0.0392157 1" />
                    <body name="FR_calf" pos="0 0 -0.225">
                        <inertial pos="0.00909091 0 -0.108636" quat="0.705775 0.0433718 0.0433718 0.705775" mass="0.22" diaginertia="0.00183194 0.00181008 4.5767e-05" />
                        <joint name="FR_calf_joint" pos="0 0 0" axis="0 -1 0" limited="true" range="0.916298 2.69653" />
                        <geom type="mesh" contype="0" conaffinity="0" group="1" rgba="1 0.423529 0.0392157 1" mesh="calf" />
                        <geom size="0.1125 0.008 0.008" pos="0 0 -0.1125" quat="0.707107 0 0.707107 0" type="box" rgba="1 0.423529 0.0392157 1" />
                        <geom size="0.01" pos="0 0 -0.225" contype="0" conaffinity="0" group="1" rgba="1 0.423529 0.0392157 1" />
                        <geom size="0.02" pos="0 0 -0.225" rgba="1 0.423529 0.0392157 1" />
                    </body>
                </body>
            </body>
            <body name="FL_hip" pos="0.226 0.055 0">
                <inertial pos="-0.003311 0.000635 3.1e-05" quat="0.689413 0.153534 0.154338 0.690882" mass="0.75" diaginertia="0.000775212 0.000502914 0.000502055" />
                <joint name="FL_hip_joint" pos="0 0 0" axis="1 0 0" limited="true" range="-1.0472 1.0472" />
                <geom type="mesh" contype="0" conaffinity="0" group="1" rgba="1 0.423529 0.0392157 1" mesh="hip" />
                <geom size="0.045 0.02" quat="0.707107 0.707107 0 0" type="cylinder" rgba="1 0.423529 0.0392157 1" />
                <body name="FL_thigh" pos="0 0.0875 0">
                    <inertial pos="-0.002 -0.023 -0.0263" quat="0.73046 0.0868634 -0.0316401 0.676669" mass="1.25" diaginertia="0.00545464 0.00531835 0.000942016" />
                    <joint name="FL_thigh_joint" pos="0 0 0" axis="0 -1 0" limited="true" range="-3.14159 1.0472" />
                    <geom type="mesh" contype="0" conaffinity="0" group="1" rgba="1 0.423529 0.0392157 1" mesh="thigh" />
                    <geom size="0.1125 0.01225 0.017" pos="-0.012 0 -0.1125" quat="0.670882 0 0.741564 0" type="box" rgba="1 0.423529 0.0392157 1" />
                    <geom size="0.045 0.02" pos="0 -0.025 0" quat="0.707107 0.707107 0 0" type="cylinder" rgba="1 0.423529 0.0392157 1" />
                    <body name="FL_calf" pos="0 0 -0.225">
                        <inertial pos="0.00909091 0 -0.108636" quat="0.705775 0.0433718 0.0433718 0.705775" mass="0.22" diaginertia="0.00183194 0.00181008 4.5767e-05" />
                        <joint name="FL_calf_joint" pos="0 0 0" axis="0 -1 0" limited="true" range="0.916298 2.69653" />
                        <geom type="mesh" contype="0" conaffinity="0" group="1" rgba="1 0.423529 0.0392157 1" mesh="calf" />
                        <geom size="0.1125 0.008 0.008" pos="0 0 -0.1125" quat="0.707107 0 0.707107 0" type="box" rgba="1 0.423529 0.0392157 1" />
                        <geom size="0.01" pos="0 0 -0.225" contype="0" conaffinity="0" group="1" rgba="1 0.423529 0.0392157 1" />
                        <geom size="0.02" pos="0 0 -0.225" rgba="1 0.423529 0.0392157 1" />
                    </body>
                </body>
            </body>
            <body name="RR_hip" pos="-0.226 -0.055 0">
                <inertial pos="0.003311 -0.000635 3.1e-05" quat="0.689413 -0.153534 -0.154338 0.690882" mass="0.75" diaginertia="0.000775212 0.000502914 0.000502055" />
                <joint name="RR_hip_joint" pos="0 0 0" axis="1 0 0" limited="true" range="-1.0472 1.0472" />
                <geom quat="0 0 0 -1" type="mesh" contype="0" conaffinity="0" group="1" rgba="1 0.423529 0.0392157 1" mesh="hip" />
                <geom size="0.045 0.02" quat="0.707107 0.707107 0 0" type="cylinder" rgba="1 0.423529 0.0392157 1" />
                <body name="RR_thigh" pos="0 -0.0875 0">
                    <inertial pos="-0.002 0.023 -0.0263" quat="0.676669 -0.0316401 0.0868634 0.73046" mass="1.25" diaginertia="0.00545464 0.00531835 0.000942016" />
                    <joint name="RR_thigh_joint" pos="0 0 0" axis="0 -1 0" limited="true" range="-3.14159 1.0472" />
                    <geom type="mesh" contype="0" conaffinity="0" group="1" rgba="1 0.423529 0.0392157 1" mesh="thigh_mirror" />
                    <geom size="0.1125 0.01225 0.017" pos="-0.012 0 -0.1125" quat="0.670882 0 0.741564 0" type="box" rgba="1 0.423529 0.0392157 1" />
                    <geom size="0.045 0.02" pos="0 0.025 0" quat="0.707107 0.707107 0 0" type="cylinder" rgba="1 0.423529 0.0392157 1" />
                    <body name="RR_calf" pos="0 0 -0.225">
                        <inertial pos="0.00909091 0 -0.108636" quat="0.705775 0.0433718 0.0433718 0.705775" mass="0.22" diaginertia="0.00183194 0.00181008 4.5767e-05" />
                        <joint name="RR_calf_joint" pos="0 0 0" axis="0 -1 0" limited="true" range="0.916298 2.69653" />
                        <geom type="mesh" contype="0" conaffinity="0" group="1" rgba="1 0.423529 0.0392157 1" mesh="calf" />
                        <geom size="0.1125 0.008 0.008" pos="0 0 -0.1125" quat="0.707107 0 0.707107 0" type="box" rgba="1 0.423529 0.0392157 1" />
                        <geom size="0.01" pos="0 0 -0.225" contype="0" conaffinity="0" group="1" rgba="1 0.423529 0.0392157 1" />
                        <geom size="0.02" pos="0 0 -0.225" rgba="1 0.423529 0.0392157 1" />
                    </body>
                </body>
            </body>
            <body name="RL_hip" pos="-0.226 0.055 0">
                <inertial pos="0.003311 0.000635 3.1e-05" quat="0.690882 -0.154338 -0.153534 0.689413" mass="0.75" diaginertia="0.000775212 0.000502914 0.000502055" />
                <joint name="RL_hip_joint" pos="0 0 0" axis="1 0 0" limited="true" range="-1.0472 1.0472" />
                <geom quat="0 0 1 0" type="mesh" contype="0" conaffinity="0" group="1" rgba="1 0.423529 0.0392157 1" mesh="hip" />
                <geom size="0.045 0.02" quat="0.707107 0.707107 0 0" type="cylinder" rgba="1 0.423529 0.0392157 1" />
                <body name="RL_thigh" pos="0 0.0875 0">
                    <inertial pos="-0.002 -0.023 -0.0263" quat="0.73046 0.0868634 -0.0316401 0.676669" mass="1.25" diaginertia="0.00545464 0.00531835 0.000942016" />
                    <joint name="RL_thigh_joint" pos="0 0 0" axis="0 -1 0" limited="true" range="-3.14159 1.0472" />
                    <geom type="mesh" contype="0" conaffinity="0" group="1" rgba="1 0.423529 0.0392157 1" mesh="thigh" />
                    <geom size="0.1125 0.01225 0.017" pos="-0.012 0 -0.1125" quat="0.670882 0 0.741564 0" type="box" rgba="1 0.423529 0.0392157 1" />
                    <geom size="0.045 0.02" pos="0 -0.025 0" quat="0.707107 0.707107 0 0" type="cylinder" rgba="1 0.423529 0.0392157 1" />
                    <body name="RL_calf" pos="0 0 -0.225">
                        <inertial pos="0.00909091 0 -0.108636" quat="0.705775 0.0433718 0.0433718 0.705775" mass="0.22" diaginertia="0.00183194 0.00181008 4.5767e-05" />
                        <joint name="RL_calf_joint" pos="0 0 0" axis="0 -1 0" limited="true" range="0.916298 2.69653" />
                        <geom type="mesh" contype="0" conaffinity="0" group="1" rgba="1 0.423529 0.0392157 1" mesh="calf" />
                        <geom size="0.1125 0.008 0.008" pos="0 0 -0.1125" quat="0.707107 0 0.707107 0" type="box" rgba="1 0.423529 0.0392157 1" />
                        <geom size="0.01" pos="0 0 -0.225" contype="0" conaffinity="0" group="1" rgba="1 0.423529 0.0392157 1" />
                        <geom size="0.02" pos="0 0 -0.225" rgba="1 0.423529 0.0392157 1" />
                    </body>
                </body>
            </body>
        </body>
    </worldbody>
</mujoco>
<actuator>
    <position name="FR_hip" joint="FR_hip_joint" kp="100"/>
    <position name="FR_thign" joint="FR_thign_joint" kp="100"/>
    <position name="FR_calf" joint="FR_calf_joint" kp="100"/>
    <position name="FL_hip" joint="FL_hip_joint" kp="100"/>
    <position name="FL_thign" joint="FL_thign_joint" kp="100"/>
    <position name="FL_calf" joint="FL_calf_joint" kp="100"/>    
    <position name="RR_hip" joint="RR_hip_joint" kp="100"/>
    <position name="RR_thign" joint="RR_thign_joint" kp="100"/>
    <position name="RR_calf" joint="RR_calf_joint" kp="100"/>    
    <position name="RL_hip" joint="RL_hip_joint" kp="100"/>
    <position name="RL_thign" joint="RL_thign_joint" kp="100"/>
    <position name="RL_calf" joint="RL_calf_joint" kp="100"/>    
</actuator>
  <sensor>
    <jointpos joint="FR_hip_joint" user="6"/>
    <jointpos joint="FR_thign_joint" user="6"/>
    <jointpos joint="FR_calf_joint" user="6"/>
    <jointpos joint="FL_hip_joint" user="6"/>
    <jointpos joint="FL_thign_joint" user="6"/>
    <jointpos joint="FL_calf_joint" user="6"/>
    <jointpos joint="RR_hip_joint" user="6"/>
    <jointpos joint="RR_thign_joint" user="6"/>
    <jointpos joint="RR_calf_joint" user="6"/>
    <jointpos joint="RL_hip_joint" user="6"/>
    <jointpos joint="RL_thign_joint" user="6"/>
    <jointpos joint="RL_calf_joint" user="6"/>

    <jointvel joint="FR_hip_joint" user="6"/>
    <jointvel joint="FR_thign_joint" user="6"/>
    <jointvel joint="FR_calf_joint" user="6"/>
    <jointvel joint="FL_hip_joint" user="6"/>
    <jointvel joint="FL_thign_joint" user="6"/>
    <jointvel joint="FL_calf_joint" user="6"/>
    <jointvel joint="RR_hip_joint" user="6"/>
    <jointvel joint="RR_thign_joint" user="6"/>
    <jointvel joint="RR_calf_joint" user="6"/>
    <jointvel joint="RL_hip_joint" user="6"/>
    <jointvel joint="RL_thign_joint" user="6"/>
    <jointvel joint="RL_calf_joint" user="6"/>

    <framequat name='orientation' objtype='site' noise='0.001' objname='imu'/>
    <framepos name='position' objtype='site' noise='0.001' objname='imu'/>
    <gyro name='angular-velocity' site='imu' noise='0.005' cutoff='34.9'/>
    <velocimeter name='linear-velocity' site='imu' noise='0.001' cutoff='30'/>
  </sensor>