<?xml version="1.0" ?>
<!-- =================================================================================== -->
<!-- |    This document was autogenerated by xacro from robot.xacro                    | -->
<!-- |    EDITING THIS FILE BY HAND IS NOT RECOMMENDED                                 | -->
<!-- =================================================================================== -->
<robot name="dog200">
  <material name="black">
    <color rgba="0.0 0.0 0.0 1.0"/>
  </material>
  <material name="blue">
    <color rgba="0.0 0.0 0.8 1.0"/>
  </material>
  <material name="green">
    <color rgba="0.0 0.8 0.0 1.0"/>
  </material>
  <material name="grey">
    <color rgba="0.2 0.2 0.2 1.0"/>
  </material>
  <material name="silver">
    <color rgba="0.9137254901960784 0.9137254901960784 0.8470588235294118 1.0"/>
  </material>
  <material name="orange">
    <color rgba="1.0 0.4235294117647059 0.0392156862745098 1.0"/>
  </material>
  <material name="brown">
    <color rgba="0.8705882352941177 0.8117647058823529 0.7647058823529411 1.0"/>
  </material>
  <material name="red">
    <color rgba="0.8 0.0 0.0 1.0"/>
  </material>
  <material name="white">
    <color rgba="1.0 1.0 1.0 1.0"/>
  </material>
  <!-- ？？？-->
  <link name="trunk">
    <visual>
      <origin rpy="0 0 0" xyz="0 0 0"/>
      <geometry>
        <mesh filename="../meshes/trunk.STL" scale="1 1 1"/>
      </geometry>
    </visual>
    <collision>
      <origin rpy="0 0 0" xyz="0 0 0"/>
      <geometry>
        <box size="0.506 0.304 0.18"/>
      </geometry>
    </collision>
    <inertial>
      <origin rpy="0 0 0" xyz="-0.00127 -0.000312 -0.009056"/>
      <mass value="26.509671"/>
      <inertia ixx="0.238293" ixy="6.5e-05" ixz="0.005717" iyy="0.98538" iyz="-0.000315" izz="1.07499"/>
    </inertial>
  </link>
  <!-- Imu is fixed to the base link -->
  <joint name="imu_link_joint" type="fixed">
    <origin rpy="0. 0. 0." xyz="0. 0. 0."/>
    <parent link="trunk"/>
    <child link="imu_link"/>
  </joint>
  <!-- Imu link -->
  <link name="imu_link">
    <inertial>
      <mass value="0.01"/>
      <origin rpy="0 0 0" xyz="0 0 0"/>
      <inertia ixx="0.000001" ixy="0" ixz="0" iyy="0.000001" iyz="0" izz="0.000001"/>
    </inertial>
    <visual>
      <origin rpy="0 0 0" xyz="0 0 0"/>
      <geometry>
        <box size="0.015 0.015 0.004"/>
      </geometry>
    </visual>
    <material name="orange">
      <color rgba="255 108 10 255"/>
    </material>
  </link>
  <joint name="FR_hip_joint" type="revolute">
    <origin rpy="0 0 0" xyz="0.35 -0.075 0"/>
    <parent link="trunk"/>
    <child link="FR_hip"/>
    <axis xyz="1 0 0"/>
    <dynamics damping="0" friction="0"/>
    <limit effort="160" lower="-0.5235987755982988" upper="0.5235987755982988" velocity="30"/>
  </joint>
  <link name="FR_hip">
    <visual>
      <origin rpy="3.141592653589793 0 0" xyz="0 0 0"/>
      <geometry>
        <mesh filename="../meshes/hip.STL" scale="1 1 1"/>
      </geometry>
      <material name="orange"/>
    </visual>
    <collision>
      <origin rpy="1.5707963267948966 0 0" xyz="0 0 0"/>
      <geometry>
        <cylinder length="0.055" radius="0.0875"/>
      </geometry>
    </collision>
    <inertial>
      <origin rpy="0 0 0" xyz="-0.011066 0.004319 3.3e-06"/>
      <mass value="2.6599"/>
      <inertia ixx="0.005441" ixy="-9.5e-05" ixz="-2e-06" iyy="0.011182" iyz="-2e-06" izz="0.007098"/>
    </inertial>
  </link>
  <joint name="FR_thigh_joint" type="revolute">
    <origin rpy="0 0 0" xyz="0 -0.10765 0"/>
    <parent link="FR_hip"/>
    <child link="FR_thigh"/>
    <axis xyz="0 -1 0"/>
    <dynamics damping="0" friction="0"/>
    <limit effort="200" lower="-1.9896753472735356" upper="0.4886921905584123" velocity="30"/>
  </joint>
  <link name="FR_thigh">
    <visual>
      <origin rpy="0 0 0" xyz="0 0 0"/>
      <geometry>
        <mesh filename="../meshes/R_thigh.STL" scale="1 1 1"/>
      </geometry>
      <material name="orange"/>
    </visual>
    <collision>
      <origin rpy="0 1.6707963267948966 0" xyz="-0.0 0 -0.175"/>
      <geometry>
        <box size="0.35 0.045 0.075"/>
      </geometry>
    </collision>
    <collision>
      <origin rpy="1.5707963267948966 0 0" xyz="0 0.0 0"/>
      <geometry>
        <cylinder length="0.055" radius="0.0875"/>
      </geometry>
    </collision>
    <inertial>
      <origin rpy="0 0 0" xyz="-0.007894 0.023943 -0.068076"/>
      <mass value="5.483708"/>
      <inertia ixx="0.100463" ixy="-0.001218" ixz="-0.00482" iyy="0.103304" iyz="-0.009831" izz="0.014712"/>
    </inertial>
  </link>
  <joint name="FR_calf_joint" type="revolute">
    <origin rpy="0 0 0" xyz="0 0 -0.35"/>
    <parent link="FR_thigh"/>
    <child link="FR_calf"/>
    <axis xyz="0 -1 0"/>
    <dynamics damping="0" friction="0"/>
    <limit effort="200" lower="1.0297442586766543" upper="2.722713633111154" velocity="10"/>
  </joint>
  <link name="FR_calf">
    <visual>
      <origin rpy="0 0 0" xyz="0 0 0"/>
      <geometry>
        <mesh filename="../meshes/calf.STL" scale="1 1 1"/>
      </geometry>
      <material name="orange"/>
    </visual>
    <collision>
      <origin rpy="0 1.5707963267948966 0" xyz="0.0 0 -0.164"/>
      <geometry>
        <box size="0.328 0.022 0.035"/>
      </geometry>
    </collision>
    <inertial>
      <origin rpy="0 0 0" xyz="0.017847 -7.7e-05 -0.147842"/>
      <mass value="0.623768"/>
      <inertia ixx="0.011073" ixy="0.0" ixz="0.000687" iyy="0.011294" iyz="1e-05" izz="0.000355"/>
    </inertial>
  </link>
  <joint name="FR_foot_fixed" type="fixed" dont_collapse="true">
    <origin rpy="0 0 0" xyz="0 0 -0.328"/>
    <parent link="FR_calf"/>
    <child link="FR_foot"/>
  </joint>
  <link name="FR_foot">
    <visual>
      <origin rpy="0 0 0" xyz="0 0 0"/>
      <geometry>
        <sphere radius="0.019999999999999997"/>
      </geometry>
      <material name="orange"/>
    </visual>
    <collision>
      <origin rpy="0 0 0" xyz="0 0 0"/>
      <geometry>
        <sphere radius="0.03"/>
      </geometry>
    </collision>
    <inertial>
      <mass value="0.02"/>
      <inertia ixx="7.2e-06" ixy="0.0" ixz="0.0" iyy="7.2e-06" iyz="0.0" izz="7.2e-06"/>
    </inertial>
  </link>
  <joint name="FL_hip_joint" type="revolute">
    <origin rpy="0 0 0" xyz="0.35 0.075 0"/>
    <parent link="trunk"/>
    <child link="FL_hip"/>
    <axis xyz="1 0 0"/>
    <dynamics damping="0" friction="0"/>
    <limit effort="160" lower="-0.5235987755982988" upper="0.5235987755982988" velocity="30"/>
  </joint>
  <link name="FL_hip">
    <visual>
      <origin rpy="0 0 0" xyz="0 0 0"/>
      <geometry>
        <mesh filename="../meshes/hip.STL" scale="1 1 1"/>
      </geometry>
      <material name="orange"/>
    </visual>
    <collision>
      <origin rpy="1.5707963267948966 0 0" xyz="0 0 0"/>
      <geometry>
        <cylinder length="0.055" radius="0.0875"/>
      </geometry>
    </collision>
    <inertial>
      <origin rpy="0 0 0" xyz="-0.011066 -0.004319 3.3e-06"/>
      <mass value="2.6599"/>
      <inertia ixx="0.005441" ixy="9.5e-05" ixz="-2e-06" iyy="0.011182" iyz="2e-06" izz="0.007098"/>
    </inertial>
  </link>
  <joint name="FL_thigh_joint" type="revolute">
    <origin rpy="0 0 0" xyz="0 0.10765 0"/>
    <parent link="FL_hip"/>
    <child link="FL_thigh"/>
    <axis xyz="0 -1 0"/>
    <dynamics damping="0" friction="0"/>
    <limit effort="200" lower="-1.9896753472735356" upper="0.4886921905584123" velocity="30"/>
  </joint>
  <link name="FL_thigh">
    <visual>
      <origin rpy="0 0 0" xyz="0 0 0"/>
      <geometry>
        <mesh filename="../meshes/L_thigh.STL" scale="1 1 1"/>
      </geometry>
      <material name="orange"/>
    </visual>
    <collision>
      <origin rpy="0 1.6707963267948966 0" xyz="-0.0 0 -0.175"/>
      <geometry>
        <box size="0.35 0.045 0.075"/>
      </geometry>
    </collision>
    <collision>
      <origin rpy="1.5707963267948966 0 0" xyz="0 -0.0 0"/>
      <geometry>
        <cylinder length="0.055" radius="0.0875"/>
      </geometry>
    </collision>
    <inertial>
      <origin rpy="0 0 0" xyz="-0.007894 -0.023943 -0.068076"/>
      <mass value="5.483708"/>
      <inertia ixx="0.100463" ixy="0.001218" ixz="-0.00482" iyy="0.103304" iyz="0.009831" izz="0.014712"/>
    </inertial>
  </link>
  <joint name="FL_calf_joint" type="revolute">
    <origin rpy="0 0 0" xyz="0 0 -0.35"/>
    <parent link="FL_thigh"/>
    <child link="FL_calf"/>
    <axis xyz="0 -1 0"/>
    <dynamics damping="0" friction="0"/>
    <limit effort="200" lower="1.0297442586766543" upper="2.722713633111154" velocity="10"/>
  </joint>
  <link name="FL_calf">
    <visual>
      <origin rpy="0 0 0" xyz="0 0 0"/>
      <geometry>
        <mesh filename="../meshes/calf.STL" scale="1 1 1"/>
      </geometry>
      <material name="orange"/>
    </visual>
    <collision>
      <origin rpy="0 1.5707963267948966 0" xyz="0.0 0 -0.164"/>
      <geometry>
        <box size="0.328 0.022 0.035"/>
      </geometry>
    </collision>
    <inertial>
      <origin rpy="0 0 0" xyz="0.017847 -7.7e-05 -0.147842"/>
      <mass value="0.623768"/>
      <inertia ixx="0.011073" ixy="0.0" ixz="0.000687" iyy="0.011294" iyz="1e-05" izz="0.000355"/>
    </inertial>
  </link>
  <joint name="FL_foot_fixed" type="fixed" dont_collapse="true">
    <origin rpy="0 0 0" xyz="0 0 -0.328"/>
    <parent link="FL_calf"/>
    <child link="FL_foot"/>
  </joint>
  <link name="FL_foot">
    <visual>
      <origin rpy="0 0 0" xyz="0 0 0"/>
      <geometry>
        <sphere radius="0.019999999999999997"/>
      </geometry>
      <material name="orange"/>
    </visual>
    <collision>
      <origin rpy="0 0 0" xyz="0 0 0"/>
      <geometry>
        <sphere radius="0.03"/>
      </geometry>
    </collision>
    <inertial>
      <mass value="0.02"/>
      <inertia ixx="7.2e-06" ixy="0.0" ixz="0.0" iyy="7.2e-06" iyz="0.0" izz="7.2e-06"/>
    </inertial>
  </link>
  <joint name="RR_hip_joint" type="revolute">
    <origin rpy="0 0 0" xyz="-0.35 -0.075 0"/>
    <parent link="trunk"/>
    <child link="RR_hip"/>
    <axis xyz="1 0 0"/>
    <dynamics damping="0" friction="0"/>
    <limit effort="160" lower="-0.5235987755982988" upper="0.5235987755982988" velocity="30"/>
  </joint>
  <link name="RR_hip">
    <visual>
      <origin rpy="3.141592653589793 3.141592653589793 0" xyz="0 0 0"/>
      <geometry>
        <mesh filename="../meshes/hip.STL" scale="1 1 1"/>
      </geometry>
      <material name="orange"/>
    </visual>
    <collision>
      <origin rpy="1.5707963267948966 0 0" xyz="0 0 0"/>
      <geometry>
        <cylinder length="0.055" radius="0.0875"/>
      </geometry>
    </collision>
    <inertial>
      <origin rpy="0 0 0" xyz="0.011066 0.004319 3.3e-06"/>
      <mass value="2.6599"/>
      <inertia ixx="0.005441" ixy="9.5e-05" ixz="2e-06" iyy="0.011182" iyz="-2e-06" izz="0.007098"/>
    </inertial>
  </link>
  <joint name="RR_thigh_joint" type="revolute">
    <origin rpy="0 0 0" xyz="0 -0.10765 0"/>
    <parent link="RR_hip"/>
    <child link="RR_thigh"/>
    <axis xyz="0 -1 0"/>
    <dynamics damping="0" friction="0"/>
    <limit effort="200" lower="-1.9896753472735356" upper="0.4886921905584123" velocity="30"/>
  </joint>
  <link name="RR_thigh">
    <visual>
      <origin rpy="0 0 0" xyz="0 0 0"/>
      <geometry>
        <mesh filename="../meshes/R_thigh.STL" scale="1 1 1"/>
      </geometry>
      <material name="orange"/>
    </visual>
    <collision>
      <origin rpy="0 1.6707963267948966 0" xyz="-0.0 0 -0.175"/>
      <geometry>
        <box size="0.35 0.045 0.075"/>
      </geometry>
    </collision>
    <collision>
      <origin rpy="1.5707963267948966 0 0" xyz="0 0.0 0"/>
      <geometry>
        <cylinder length="0.055" radius="0.0875"/>
      </geometry>
    </collision>
    <inertial>
      <origin rpy="0 0 0" xyz="-0.007894 0.023943 -0.068076"/>
      <mass value="5.483708"/>
      <inertia ixx="0.100463" ixy="-0.001218" ixz="-0.00482" iyy="0.103304" iyz="-0.009831" izz="0.014712"/>
    </inertial>
  </link>
  <joint name="RR_calf_joint" type="revolute">
    <origin rpy="0 0 0" xyz="0 0 -0.35"/>
    <parent link="RR_thigh"/>
    <child link="RR_calf"/>
    <axis xyz="0 -1 0"/>
    <dynamics damping="0" friction="0"/>
    <limit effort="200" lower="1.0297442586766543" upper="2.722713633111154" velocity="10"/>
  </joint>
  <link name="RR_calf">
    <visual>
      <origin rpy="0 0 0" xyz="0 0 0"/>
      <geometry>
        <mesh filename="../meshes/calf.STL" scale="1 1 1"/>
      </geometry>
      <material name="orange"/>
    </visual>
    <collision>
      <origin rpy="0 1.5707963267948966 0" xyz="0.0 0 -0.164"/>
      <geometry>
        <box size="0.328 0.022 0.035"/>
      </geometry>
    </collision>
    <inertial>
      <origin rpy="0 0 0" xyz="0.017847 -7.7e-05 -0.147842"/>
      <mass value="0.623768"/>
      <inertia ixx="0.011073" ixy="0.0" ixz="0.000687" iyy="0.011294" iyz="1e-05" izz="0.000355"/>
    </inertial>
  </link>
  <joint name="RR_foot_fixed" type="fixed" dont_collapse="true">
    <origin rpy="0 0 0" xyz="0 0 -0.328"/>
    <parent link="RR_calf"/>
    <child link="RR_foot"/>
  </joint>
  <link name="RR_foot">
    <visual>
      <origin rpy="0 0 0" xyz="0 0 0"/>
      <geometry>
        <sphere radius="0.019999999999999997"/>
      </geometry>
      <material name="orange"/>
    </visual>
    <collision>
      <origin rpy="0 0 0" xyz="0 0 0"/>
      <geometry>
        <sphere radius="0.03"/>
      </geometry>
    </collision>
    <inertial>
      <mass value="0.02"/>
      <inertia ixx="7.2e-06" ixy="0.0" ixz="0.0" iyy="7.2e-06" iyz="0.0" izz="7.2e-06"/>
    </inertial>
  </link>
  <joint name="RL_hip_joint" type="revolute">
    <origin rpy="0 0 0" xyz="-0.35 0.075 0"/>
    <parent link="trunk"/>
    <child link="RL_hip"/>
    <axis xyz="1 0 0"/>
    <dynamics damping="0" friction="0"/>
    <limit effort="160" lower="-0.5235987755982988" upper="0.5235987755982988" velocity="30"/>
  </joint>
  <link name="RL_hip">
    <visual>
      <origin rpy="0 3.141592653589793 0" xyz="0 0 0"/>
      <geometry>
        <mesh filename="../meshes/hip.STL" scale="1 1 1"/>
      </geometry>
      <material name="orange"/>
    </visual>
    <collision>
      <origin rpy="1.5707963267948966 0 0" xyz="0 0 0"/>
      <geometry>
        <cylinder length="0.055" radius="0.0875"/>
      </geometry>
    </collision>
    <inertial>
      <origin rpy="0 0 0" xyz="0.011066 -0.004319 3.3e-06"/>
      <mass value="2.6599"/>
      <inertia ixx="0.005441" ixy="-9.5e-05" ixz="2e-06" iyy="0.011182" iyz="2e-06" izz="0.007098"/>
    </inertial>
  </link>
  <joint name="RL_thigh_joint" type="revolute">
    <origin rpy="0 0 0" xyz="0 0.10765 0"/>
    <parent link="RL_hip"/>
    <child link="RL_thigh"/>
    <axis xyz="0 -1 0"/>
    <dynamics damping="0" friction="0"/>
    <limit effort="200" lower="-1.9896753472735356" upper="0.4886921905584123" velocity="30"/>
  </joint>
  <link name="RL_thigh">
    <visual>
      <origin rpy="0 0 0" xyz="0 0 0"/>
      <geometry>
        <mesh filename="../meshes/L_thigh.STL" scale="1 1 1"/>
      </geometry>
      <material name="orange"/>
    </visual>
    <collision>
      <origin rpy="0 1.6707963267948966 0" xyz="-0.0 0 -0.175"/>
      <geometry>
        <box size="0.35 0.045 0.075"/>
      </geometry>
    </collision>
    <collision>
      <origin rpy="1.5707963267948966 0 0" xyz="0 -0.0 0"/>
      <geometry>
        <cylinder length="0.055" radius="0.0875"/>
      </geometry>
    </collision>
    <inertial>
      <origin rpy="0 0 0" xyz="-0.007894 -0.023943 -0.068076"/>
      <mass value="5.483708"/>
      <inertia ixx="0.100463" ixy="0.001218" ixz="-0.00482" iyy="0.103304" iyz="0.009831" izz="0.014712"/>
    </inertial>
  </link>
  <joint name="RL_calf_joint" type="revolute">
    <origin rpy="0 0 0" xyz="0 0 -0.35"/>
    <parent link="RL_thigh"/>
    <child link="RL_calf"/>
    <axis xyz="0 -1 0"/>
    <dynamics damping="0" friction="0"/>
    <limit effort="200" lower="1.0297442586766543" upper="2.722713633111154" velocity="10"/>
  </joint>
  <link name="RL_calf">
    <visual>
      <origin rpy="0 0 0" xyz="0 0 0"/>
      <geometry>
        <mesh filename="../meshes/calf.STL" scale="1 1 1"/>
      </geometry>
      <material name="orange"/>
    </visual>
    <collision>
      <origin rpy="0 1.5707963267948966 0" xyz="0.0 0 -0.164"/>
      <geometry>
        <box size="0.328 0.022 0.035"/>
      </geometry>
    </collision>
    <inertial>
      <origin rpy="0 0 0" xyz="0.017847 -7.7e-05 -0.147842"/>
      <mass value="0.623768"/>
      <inertia ixx="0.011073" ixy="0.0" ixz="0.000687" iyy="0.011294" iyz="1e-05" izz="0.000355"/>
    </inertial>
  </link>
  <joint name="RL_foot_fixed" type="fixed" dont_collapse="true">
    <origin rpy="0 0 0" xyz="0 0 -0.328"/>
    <parent link="RL_calf"/>
    <child link="RL_foot"/>
  </joint>
  <link name="RL_foot">
    <visual>
      <origin rpy="0 0 0" xyz="0 0 0"/>
      <geometry>
        <sphere radius="0.019999999999999997"/>
      </geometry>
      <material name="orange"/>
    </visual>
    <collision>
      <origin rpy="0 0 0" xyz="0 0 0"/>
      <geometry>
        <sphere radius="0.03"/>
      </geometry>
    </collision>
    <inertial>
      <mass value="0.02"/>
      <inertia ixx="7.2e-06" ixy="0.0" ixz="0.0" iyy="7.2e-06" iyz="0.0" izz="7.2e-06"/>
    </inertial>
  </link>
</robot>

