<mujoco model="dog200">
    <compiler angle="radian" meshdir="meshes/"/>
    <asset>
        <mesh name="trunk" file="trunk.STL" />
        <mesh name="LF_HIP" file="LF_HIP.STL" />
        <mesh name="R_thigh" file="R_thigh.STL" />
        <mesh name="calf" file="calf.STL" />
        <mesh name="L_thigh" file="L_thigh.STL" />
    </asset>
    <worldbody>
        <body name="trunk" pos="0 0 1.0">
            <inertial pos="0.00789711 0.00953951 -0.0051841" quat="0.0205161 0.711371 0.0195777 0.702245" mass="27.3263" diaginertia="1.18815 1.09304 0.305078" />
            <joint name="floating_base_joint" type="free" />
            <geom type="mesh" contype="0" conaffinity="0" group="1" mesh="trunk" />
            <geom size="0.253 0.152 0.09" type="box" />
            <geom size="0.0075 0.0075 0.002" type="box" contype="0" conaffinity="0" group="1" />

            <body name="FL_hip" pos="0.35 0.075 0">
                <inertial pos="-0.011504 -0.000224 -1.3e-05" quat="0.498478 0.498792 0.501765 0.500957" mass="2.676" diaginertia="0.0113232 0.007225 0.00545482" />
                <joint name="FL_hip_joint" pos="0 0 0" axis="1 0 0" limited="true" range="-0.523599 0.523599" />
                <geom type="mesh" contype="0" conaffinity="0" group="1" rgba="1 0.423529 0.0392157 1" mesh="LF_HIP" />
                <geom size="0.0875 0.0275" quat="0.707107 0.707107 0 0" type="cylinder" rgba="1 0.423529 0.0392157 1" />
                <body name="FL_thigh" pos="0 0.10765 0">
                    <inertial pos="-0.007531 -0.02581 -0.050382" quat="0.74949 0.0608 -0.0104963 0.659134" mass="4.73942" diaginertia="0.0736307 0.0691052 0.0113391" />
                    <joint name="FL_thigh_joint" pos="0 0 0" axis="0 -1 0" limited="true" range="-1.98968 0.488692" />
                    <geom type="mesh" contype="0" conaffinity="0" group="1" rgba="1 0.423529 0.0392157 1" mesh="L_thigh" />
                    <geom size="0.175 0.0225 0.0375" pos="0 0 -0.175" quat="0.670882 0 0.741564 0" type="box" rgba="1 0.423529 0.0392157 1" />
                    <geom size="0.0875 0.0275" quat="0.707107 0.707107 0 0" type="cylinder" rgba="1 0.423529 0.0392157 1" />
                    <body name="FL_calf" pos="0 0 -0.35">
                        <inertial pos="0.0112318 7.49565e-05 -0.146471" quat="0.70682 -0.00486107 -0.00436292 0.707363" mass="0.753616" diaginertia="0.0150568 0.0148607 0.000362318" />
                        <joint name="FL_calf_joint" pos="0 0 0" axis="0 -1 0" limited="true" range="1.02974 2.72271" />
                        <geom type="mesh" contype="0" conaffinity="0" group="1" rgba="1 0.423529 0.0392157 1" mesh="calf" />
                        <geom size="0.164 0.011 0.0175" pos="0 0 -0.164" quat="0.707107 0 0.707107 0" type="box" rgba="1 0.423529 0.0392157 1" />
                        <geom size="0.02" pos="0 0 -0.328" contype="0" conaffinity="0" group="1" rgba="1 0.423529 0.0392157 1" />
                        <geom size="0.03" pos="0 0 -0.328" rgba="1 0.423529 0.0392157 1" />
                    </body>
                </body>
            </body>
            <body name="FR_hip" pos="0.35 -0.075 0">
                <inertial pos="-0.011504 0.000224 1.3e-05" quat="0.501765 0.500957 0.498478 0.498792" mass="2.676" diaginertia="0.0113232 0.007225 0.00545482" />
                <joint name="FR_hip_joint" pos="0 0 0" axis="1 0 0" limited="true" range="-0.523599 0.523599" />
                <geom quat="0 1 0 0" type="mesh" contype="0" conaffinity="0" group="1" rgba="1 0.423529 0.0392157 1" mesh="LF_HIP" />
                <geom size="0.0875 0.0275" quat="0.707107 0.707107 0 0" type="cylinder" rgba="1 0.423529 0.0392157 1" />
                <body name="FR_thigh" pos="0 -0.10765 0">
                    <inertial pos="-0.007538 0.024625 -0.050384" quat="0.992524 -0.11444 0.0295516 -0.0304463" mass="4.73942" diaginertia="0.0858268 0.0755596 0.0261026" />
                    <joint name="FR_thigh_joint" pos="0 0 0" axis="0 -1 0" limited="true" range="-1.98968 0.488692" />
                    <geom type="mesh" contype="0" conaffinity="0" group="1" rgba="1 0.423529 0.0392157 1" mesh="R_thigh" />
                    <geom size="0.175 0.0225 0.0375" pos="0 0 -0.175" quat="0.670882 0 0.741564 0" type="box" rgba="1 0.423529 0.0392157 1" />
                    <geom size="0.0875 0.0275" quat="0.707107 0.707107 0 0" type="cylinder" rgba="1 0.423529 0.0392157 1" />
                    <body name="FR_calf" pos="0 0 -0.35">
                        <inertial pos="0.0112318 7.49565e-05 -0.146471" quat="0.70682 -0.00486107 -0.00436292 0.707363" mass="0.753616" diaginertia="0.0150568 0.0148607 0.000362318" />
                        <joint name="FR_calf_joint" pos="0 0 0" axis="0 -1 0" limited="true" range="1.02974 2.72271" />
                        <geom type="mesh" contype="0" conaffinity="0" group="1" rgba="1 0.423529 0.0392157 1" mesh="calf" />
                        <geom size="0.164 0.011 0.0175" pos="0 0 -0.164" quat="0.707107 0 0.707107 0" type="box" rgba="1 0.423529 0.0392157 1" />
                        <geom size="0.02" pos="0 0 -0.328" contype="0" conaffinity="0" group="1" rgba="1 0.423529 0.0392157 1" />
                        <geom size="0.03" pos="0 0 -0.328" rgba="1 0.423529 0.0392157 1" />
                    </body>
                </body>
            </body>

            <body name="RL_hip" pos="-0.35 0.075 0">
                <inertial pos="0.011504 -0.000224 1.3e-05" quat="0.500957 0.501765 0.498792 0.498478" mass="2.676" diaginertia="0.0113232 0.007225 0.00545482" />
                <joint name="RL_hip_joint" pos="0 0 0" axis="1 0 0" limited="true" range="-0.523599 0.523599" />
                <geom quat="0 0 1 0" type="mesh" contype="0" conaffinity="0" group="1" rgba="1 0.423529 0.0392157 1" mesh="LF_HIP" />
                <geom size="0.0875 0.0275" quat="0.707107 0.707107 0 0" type="cylinder" rgba="1 0.423529 0.0392157 1" />
                <body name="RL_thigh" pos="0 0.10765 0">
                    <inertial pos="-0.007531 -0.02581 -0.050382" quat="0.74949 0.0608 -0.0104963 0.659134" mass="4.73942" diaginertia="0.0736307 0.0691052 0.0113391" />
                    <joint name="RL_thigh_joint" pos="0 0 0" axis="0 -1 0" limited="true" range="-1.98968 0.488692" />
                    <geom type="mesh" contype="0" conaffinity="0" group="1" rgba="1 0.423529 0.0392157 1" mesh="L_thigh" />
                    <geom size="0.175 0.0225 0.0375" pos="0 0 -0.175" quat="0.670882 0 0.741564 0" type="box" rgba="1 0.423529 0.0392157 1" />
                    <geom size="0.0875 0.0275" quat="0.707107 0.707107 0 0" type="cylinder" rgba="1 0.423529 0.0392157 1" />
                    <body name="RL_calf" pos="0 0 -0.35">
                        <inertial pos="0.0112318 7.49565e-05 -0.146471" quat="0.70682 -0.00486107 -0.00436292 0.707363" mass="0.753616" diaginertia="0.0150568 0.0148607 0.000362318" />
                        <joint name="RL_calf_joint" pos="0 0 0" axis="0 -1 0" limited="true" range="1.02974 2.72271" />
                        <geom type="mesh" contype="0" conaffinity="0" group="1" rgba="1 0.423529 0.0392157 1" mesh="calf" />
                        <geom size="0.164 0.011 0.0175" pos="0 0 -0.164" quat="0.707107 0 0.707107 0" type="box" rgba="1 0.423529 0.0392157 1" />
                        <geom size="0.02" pos="0 0 -0.328" contype="0" conaffinity="0" group="1" rgba="1 0.423529 0.0392157 1" />
                        <geom size="0.03" pos="0 0 -0.328" rgba="1 0.423529 0.0392157 1" />
                    </body>
                </body>
            </body>
            <body name="RR_hip" pos="-0.35 -0.075 0">
                <inertial pos="0.011504 0.000224 -1.3e-05" quat="0.498792 0.498478 0.500957 0.501765" mass="2.676" diaginertia="0.0113232 0.007225 0.00545482" />
                <joint name="RR_hip_joint" pos="0 0 0" axis="1 0 0" limited="true" range="-0.523599 0.523599" />
                <geom quat="0 0 0 -1" type="mesh" contype="0" conaffinity="0" group="1" rgba="1 0.423529 0.0392157 1" mesh="LF_HIP" />
                <geom size="0.0875 0.0275" quat="0.707107 0.707107 0 0" type="cylinder" rgba="1 0.423529 0.0392157 1" />
                <body name="RR_thigh" pos="0 -0.10765 0">
                    <inertial pos="-0.007538 0.024625 -0.050384" quat="0.992524 -0.11444 0.0295516 -0.0304463" mass="4.73942" diaginertia="0.0858268 0.0755596 0.0261026" />
                    <joint name="RR_thigh_joint" pos="0 0 0" axis="0 -1 0" limited="true" range="-1.98968 0.488692" />
                    <geom type="mesh" contype="0" conaffinity="0" group="1" rgba="1 0.423529 0.0392157 1" mesh="R_thigh" />
                    <geom size="0.175 0.0225 0.0375" pos="0 0 -0.175" quat="0.670882 0 0.741564 0" type="box" rgba="1 0.423529 0.0392157 1" />
                    <geom size="0.0875 0.0275" quat="0.707107 0.707107 0 0" type="cylinder" rgba="1 0.423529 0.0392157 1" />
                    <body name="RR_calf" pos="0 0 -0.35">
                        <inertial pos="0.0112318 7.49565e-05 -0.146471" quat="0.70682 -0.00486107 -0.00436292 0.707363" mass="0.753616" diaginertia="0.0150568 0.0148607 0.000362318" />
                        <joint name="RR_calf_joint" pos="0 0 0" axis="0 -1 0" limited="true" range="1.02974 2.72271" />
                        <geom type="mesh" contype="0" conaffinity="0" group="1" rgba="1 0.423529 0.0392157 1" mesh="calf" />
                        <geom size="0.164 0.011 0.0175" pos="0 0 -0.164" quat="0.707107 0 0.707107 0" type="box" rgba="1 0.423529 0.0392157 1" />
                        <geom size="0.02" pos="0 0 -0.328" contype="0" conaffinity="0" group="1" rgba="1 0.423529 0.0392157 1" />
                        <geom size="0.03" pos="0 0 -0.328" rgba="1 0.423529 0.0392157 1" />
                    </body>
                </body>
            </body>
        </body>
    </worldbody>
<actuator>
    <motor name="FL_hip" joint="FL_hip_joint" />
    <motor name="FL_thigh" joint="FL_thigh_joint" />
    <motor name="FL_calf" joint="FL_calf_joint" /> 
    <motor name="FR_hip" joint="FR_hip_joint" />
    <motor name="FR_thigh" joint="FR_thigh_joint" />
    <motor name="FR_calf" joint="FR_calf_joint" />
    <motor name="RL_hip" joint="RL_hip_joint" />
    <motor name="RL_thigh" joint="RL_thigh_joint" />
    <motor name="RL_calf" joint="RL_calf_joint" />    
    <motor name="RR_hip" joint="RR_hip_joint" />
    <motor name="RR_thigh" joint="RR_thigh_joint" />
    <motor name="RR_calf" joint="RR_calf_joint" />    
</actuator>
</mujoco>
